2020-12-15 19:09:22,396 INFO    MainThread:29406 [internal.py:wandb_internal():63] W&B internal server running at pid: 29406
2020-12-15 19:09:22,398 DEBUG   HandlerThread:29406 [handler.py:handle_request():55] handle_request: check_version
2020-12-15 19:09:22,438 INFO    WriterThread:29406 [datastore.py:open_for_write():76] open: /home/cse/staff/sid97.cstaff/Zero-DCE/Zero-DCE_code/wandb/run-20201215_190921-1oumlk7e/run-1oumlk7e.wandb
2020-12-15 19:09:22,442 DEBUG   SenderThread:29406 [sender.py:send():90] send: header
2020-12-15 19:09:22,442 DEBUG   SenderThread:29406 [sender.py:send():90] send: request
2020-12-15 19:09:22,442 DEBUG   SenderThread:29406 [sender.py:send_request():99] send_request: check_version
2020-12-15 19:09:22,445 DEBUG   Thread-4  :29406 [connectionpool.py:_new_conn():975] Starting new HTTPS connection (1): pypi.org:443
2020-12-15 19:09:22,469 DEBUG   SenderThread:29406 [sender.py:send():90] send: run
2020-12-15 19:09:22,564 DEBUG   SenderThread:29406 [cmd.py:execute():719] Popen(['git', 'cat-file', '--batch-check'], cwd=/home/cse/staff/sid97.cstaff/Zero-DCE, universal_newlines=False, shell=None, istream=<valid stream>)
2020-12-15 19:09:22,717 DEBUG   SenderThread:29406 [connectionpool.py:_new_conn():975] Starting new HTTPS connection (1): api.wandb.ai:443
2020-12-15 19:09:23,897 DEBUG   SenderThread:29406 [connectionpool.py:_new_conn():975] Starting new HTTPS connection (1): api.wandb.ai:443
2020-12-15 19:09:26,144 DEBUG   SenderThread:29406 [connectionpool.py:_new_conn():975] Starting new HTTPS connection (1): api.wandb.ai:443
2020-12-15 19:09:26,146 ERROR   SenderThread:29406 [retry.py:__call__():111] Retry attempt failed:
Traceback (most recent call last):
  File "/home/cse/staff/sid97.cstaff/anaconda3/envs/zerodce_env/lib/python3.7/site-packages/urllib3/connectionpool.py", line 696, in urlopen
    self._prepare_proxy(conn)
  File "/home/cse/staff/sid97.cstaff/anaconda3/envs/zerodce_env/lib/python3.7/site-packages/urllib3/connectionpool.py", line 964, in _prepare_proxy
    conn.connect()
  File "/home/cse/staff/sid97.cstaff/anaconda3/envs/zerodce_env/lib/python3.7/site-packages/urllib3/connection.py", line 366, in connect
    self._tunnel()
  File "/home/cse/staff/sid97.cstaff/anaconda3/envs/zerodce_env/lib/python3.7/http/client.py", line 927, in _tunnel
    message.strip()))
OSError: Tunnel connection failed: 302 Moved Temporarily

During handling of the above exception, another exception occurred:

Traceback (most recent call last):
  File "/home/cse/staff/sid97.cstaff/anaconda3/envs/zerodce_env/lib/python3.7/site-packages/requests/adapters.py", line 449, in send
    timeout=timeout
  File "/home/cse/staff/sid97.cstaff/anaconda3/envs/zerodce_env/lib/python3.7/site-packages/urllib3/connectionpool.py", line 756, in urlopen
    method, url, error=e, _pool=self, _stacktrace=sys.exc_info()[2]
  File "/home/cse/staff/sid97.cstaff/anaconda3/envs/zerodce_env/lib/python3.7/site-packages/urllib3/util/retry.py", line 573, in increment
    raise MaxRetryError(_pool, url, error or ResponseError(cause))
urllib3.exceptions.MaxRetryError: HTTPSConnectionPool(host='api.wandb.ai', port=443): Max retries exceeded with url: /graphql (Caused by ProxyError('Cannot connect to proxy.', OSError('Tunnel connection failed: 302 Moved Temporarily')))

During handling of the above exception, another exception occurred:

Traceback (most recent call last):
  File "/home/cse/staff/sid97.cstaff/anaconda3/envs/zerodce_env/lib/python3.7/site-packages/wandb/old/retry.py", line 96, in __call__
    result = self._call_fn(*args, **kwargs)
  File "/home/cse/staff/sid97.cstaff/anaconda3/envs/zerodce_env/lib/python3.7/site-packages/wandb/sdk/internal/internal_api.py", line 130, in execute
    return self.client.execute(*args, **kwargs)
  File "/home/cse/staff/sid97.cstaff/anaconda3/envs/zerodce_env/lib/python3.7/site-packages/wandb/vendor/gql-0.2.0/gql/client.py", line 52, in execute
    result = self._get_result(document, *args, **kwargs)
  File "/home/cse/staff/sid97.cstaff/anaconda3/envs/zerodce_env/lib/python3.7/site-packages/wandb/vendor/gql-0.2.0/gql/client.py", line 60, in _get_result
    return self.transport.execute(document, *args, **kwargs)
  File "/home/cse/staff/sid97.cstaff/anaconda3/envs/zerodce_env/lib/python3.7/site-packages/wandb/vendor/gql-0.2.0/gql/transport/requests.py", line 38, in execute
    request = requests.post(self.url, **post_args)
  File "/home/cse/staff/sid97.cstaff/anaconda3/envs/zerodce_env/lib/python3.7/site-packages/requests/api.py", line 119, in post
    return request('post', url, data=data, json=json, **kwargs)
  File "/home/cse/staff/sid97.cstaff/anaconda3/envs/zerodce_env/lib/python3.7/site-packages/requests/api.py", line 61, in request
    return session.request(method=method, url=url, **kwargs)
  File "/home/cse/staff/sid97.cstaff/anaconda3/envs/zerodce_env/lib/python3.7/site-packages/requests/sessions.py", line 542, in request
    resp = self.send(prep, **send_kwargs)
  File "/home/cse/staff/sid97.cstaff/anaconda3/envs/zerodce_env/lib/python3.7/site-packages/requests/sessions.py", line 655, in send
    r = adapter.send(request, **kwargs)
  File "/home/cse/staff/sid97.cstaff/anaconda3/envs/zerodce_env/lib/python3.7/site-packages/requests/adapters.py", line 510, in send
    raise ProxyError(e, request=request)
requests.exceptions.ProxyError: HTTPSConnectionPool(host='api.wandb.ai', port=443): Max retries exceeded with url: /graphql (Caused by ProxyError('Cannot connect to proxy.', OSError('Tunnel connection failed: 302 Moved Temporarily')))
2020-12-15 19:09:30,235 DEBUG   SenderThread:29406 [connectionpool.py:_new_conn():975] Starting new HTTPS connection (1): api.wandb.ai:443
2020-12-15 19:09:38,258 DEBUG   SenderThread:29406 [connectionpool.py:_new_conn():975] Starting new HTTPS connection (1): api.wandb.ai:443
2020-12-15 19:09:41,546 WARNING MainThread:29406 [internal.py:wandb_internal():117] Internal process interrupt: 1
2020-12-15 19:09:56,715 DEBUG   SenderThread:29406 [connectionpool.py:_new_conn():975] Starting new HTTPS connection (1): api.wandb.ai:443
2020-12-15 19:10:13,270 WARNING MainThread:29406 [internal.py:wandb_internal():117] Internal process interrupt: 2
2020-12-15 19:10:13,271 ERROR   MainThread:29406 [internal.py:wandb_internal():120] Internal process interrupted.
2020-12-15 19:10:13,476 INFO    WriterThread:29406 [datastore.py:close():257] close: /home/cse/staff/sid97.cstaff/Zero-DCE/Zero-DCE_code/wandb/run-20201215_190921-1oumlk7e/run-1oumlk7e.wandb
2020-12-15 19:10:13,525 INFO    HandlerThread:29406 [handler.py:finish():271] shutting down handler
2020-12-15 19:10:36,458 DEBUG   SenderThread:29406 [connectionpool.py:_new_conn():975] Starting new HTTPS connection (1): api.wandb.ai:443
2020-12-15 19:11:46,359 DEBUG   SenderThread:29406 [connectionpool.py:_new_conn():975] Starting new HTTPS connection (1): api.wandb.ai:443
2020-12-15 19:14:23,298 DEBUG   SenderThread:29406 [connectionpool.py:_new_conn():975] Starting new HTTPS connection (1): api.wandb.ai:443
2020-12-15 19:19:20,527 DEBUG   SenderThread:29406 [connectionpool.py:_new_conn():975] Starting new HTTPS connection (1): api.wandb.ai:443
2020-12-15 19:24:50,446 DEBUG   SenderThread:29406 [connectionpool.py:_new_conn():975] Starting new HTTPS connection (1): api.wandb.ai:443
